# 如何编写测试

- [如何编写测试](#如何编写测试)
  - [测试函数剖析](#测试函数剖析)
  - [使用 assert! 宏来检查结果](#使用-assert-宏来检查结果)
  - [使用 assert_eq! 和 assert_ne! 宏来测试相等](#使用-assert_eq-和-assert_ne-宏来测试相等)
  - [自定义失败信息](#自定义失败信息)
  - [使用 should_panic 检查 panic](#使用-should_panic-检查-panic)
  - [将 Result<T, E> 用于测试](#将-resultt-e-用于测试)

Rust 中的测试函数是用来验证非测试代码是否按照期望的方式运行的。测试函数体通常执行如下三种操作：

- 设置任何所需的数据或状态
- 运行需要测试的代码
- 断言其结果是我们所期望的

Rust 提供的专门用来编写测试的功能：

- `test` 属性
- 一些宏
- `should_panic` 属性

## 测试函数剖析

为了将一个函数变成测试函数，需要在 `fn` 行之前加上 `#[test]`。当使用 `cargo test` 命令运行测试时，Rust 会构建一个测试执行程序用来调用标记了 `test` 属性的函数，并报告每一个测试是通过还是失败。

当使用 Cargo 新建一个库项目时，它会自动为我们生成一个测试模块和一个测试函数。

```bash
$ cargo new adder --lib
     Created library `adder` project
$ cd adder
```

adder 库中 `src/lib.rs` 的内容应该看起来如下所示：

```rust
#[cfg(test)]
mod tests {
    #[test]
    fn it_works() {
        let result = 2 + 2;
        assert_eq!(result, 4);
    }
}
```

现在让我们暂时忽略 `tests` 模块和 `#[cfg(test)]` 注解，并只关注函数来了解其如何工作。

注意 `fn` 行之前的 `#[test]`：这个属性表明这是一个测试函数，这样测试执行者就知道将其作为测试处理。因为也可以在 `tests` 模块中拥有非测试的函数来帮助我们建立通用场景或进行常见操作，所以需要使用 `#[test]` 属性标明哪些函数是测试。

函数体通过使用 `assert_eq!` 宏来断言 2 加 2 等于 4。

`cargo test` 命令会运行项目中所有的测试，如下所示：

```rust
$ cargo test
   Compiling adder v0.1.0 (/home/endruz/code/endruz/hello-rust/11.1/adder)
    Finished test [unoptimized + debuginfo] target(s) in 0.89s
     Running unittests src/lib.rs (target/debug/deps/adder-526769bbba97b5af)

running 1 test
test tests::it_works ... ok

test result: ok. 1 passed; 0 failed; 0 ignored; 0 measured; 0 filtered out; finished in 0.00s

   Doc-tests adder

running 0 tests

test result: ok. 0 passed; 0 failed; 0 ignored; 0 measured; 0 filtered out; finished in 0.00s
```

Cargo 编译并运行了测试。在 `Compiling`、`Finished` 和 `Running` 这几行之后，可以看到 `running 1 test` 这一行。下一行显示了生成的测试函数的名称，它是 `it_works`，以及测试的运行结果，`ok`。接着可以看到全体测试运行结果的摘要：`test result: ok`. 意味着所有测试都通过了。

- `1 passed; 0 failed` 表示通过或失败的测试数量。
- 因为之前我们并没有将任何测试标记为忽略，所以摘要中会显示 `0 ignored`。
- 我们也没有过滤需要运行的测试，所以摘要中会显示 `0 filtered out`。
- `0 measured` 统计是针对性能测试的。性能测试（`benchmark tests`）在编写本书时，仍只能用于 Rust 开发版（nightly Rust）。

测试输出中的以 `Doc-tests adder` 开头的这一部分是所有文档测试的结果。我们现在并没有任何文档测试，不过 Rust 会编译任何在 API 文档中的代码示例。这个功能帮助我们使文档和代码保持同步！

让我们增加另一个测试，不过这一次是一个会失败的测试！当测试函数中出现 `panic` 时测试就失败了。每一个测试都在一个新线程中运行，当主线程发现测试线程异常了，就将对应测试标记为失败。

```rust
#[cfg(test)]
mod tests {
    #[test]
    fn exploration() {
        assert_eq!(2 + 2, 4);
    }

    #[test]
    fn another() {
        panic!("Make this test fail");
    }
}
```

再次 `cargo test` 运行测试。输出应该如下，它表明 `exploration` 测试通过了而 `another` 失败了：

```bash
$ cargo test
   Compiling adder v0.1.0 (/home/endruz/code/endruz/hello-rust/11.1/adder)
    Finished test [unoptimized + debuginfo] target(s) in 0.31s
     Running unittests src/lib.rs (target/debug/deps/adder-526769bbba97b5af)

running 2 tests
test tests::another ... FAILED
test tests::exploration ... ok

failures:

---- tests::another stdout ----
thread 'tests::another' panicked at 'Make this test fail', src/lib.rs:10:9
note: run with `RUST_BACKTRACE=1` environment variable to display a backtrace


failures:
    tests::another

test result: FAILED. 1 passed; 1 failed; 0 ignored; 0 measured; 0 filtered out; finished in 0.00s

error: test failed, to rerun pass '--lib'
```

`test tests::another` 这一行是 `FAILED` 而不是 `ok` 了。在单独测试结果和摘要之间多了两个新的部分：

- 第一个部分显示了测试失败的详细原因。在这个例子中，`another` 因为在 `src/lib.rs` 的第 10 行 `panicked at 'Make this test fail'` 而失败。
- 下一部分列出了所有失败的测试，这在有很多测试和很多失败测试的详细输出时很有帮助。我们可以通过使用失败测试的名称来只运行这个测试，以便调试。

最后是摘要行：总体上讲，测试结果是 `FAILED`。有一个测试通过和一个测试失败。

## 使用 assert! 宏来检查结果

`assert!` 宏由标准库提供，在希望确保测试中一些条件为 `true` 时非常有用。需要向 `assert!` 宏提供一个求值为布尔值的参数。如果值是 `true`，`assert!` 什么也不做，同时测试会通过。如果值为 `false`，`assert!` 调用 `panic!` 宏，这会导致测试失败。

`src/lib.rs` 内容如下：

```rust
#[cfg(test)]
mod tests {
    use super::*;

    #[test]
    fn larger_can_hold_smaller() {
        let larger = Rectangle {
            width: 8,
            height: 7,
        };
        let smaller = Rectangle {
            width: 5,
            height: 1,
        };
        assert!(larger.can_hold(&smaller));
    }

    #[test]
    fn smaller_cannot_hold_larger() {
        let larger = Rectangle {
            width: 8,
            height: 7,
        };
        let smaller = Rectangle {
            width: 5,
            height: 1,
        };

        assert!(!smaller.can_hold(&larger));
    }
}

pub struct Rectangle {
    width: u32,
    height: u32,
}

impl Rectangle {
    pub fn can_hold(&self, other: &Rectangle) -> bool {
        self.width > other.width && self.height > other.height
    }
}
```

`cargo test` 运行测试：

```bash
$ cargo test
   Compiling adder v0.1.0 (/home/endruz/code/endruz/hello-rust/11.1/adder)
    Finished test [unoptimized + debuginfo] target(s) in 0.24s
     Running unittests src/lib.rs (target/debug/deps/adder-526769bbba97b5af)

running 2 tests
test tests::smaller_cannot_hold_larger ... ok
test tests::larger_can_hold_smaller ... ok

test result: ok. 2 passed; 0 failed; 0 ignored; 0 measured; 0 filtered out; finished in 0.00s

   Doc-tests adder

running 0 tests

test result: ok. 0 passed; 0 failed; 0 ignored; 0 measured; 0 filtered out; finished in 0.00s
```

## 使用 assert_eq! 和 assert_ne! 宏来测试相等

`assert_eq!` 和 `assert_ne!` 这两个宏分别比较两个值是相等还是不相等。当断言失败时他们也会打印出这两个值具体是什么，以便于观察测试为什么失败。

`src/lib.rs` 内容如下：

```rust
#[cfg(test)]
mod tests {
    use super::*;

    #[test]
    fn it_adds_two() {
        assert_eq!(4, add_two(2));
    }
}

pub fn add_two(a: i32) -> i32 {
    a + 2
}
```

`cargo test` 运行测试：

```bash
$ cargo test
   Compiling adder v0.1.0 (/home/endruz/code/endruz/hello-rust/11.1/adder)
    Finished test [unoptimized + debuginfo] target(s) in 0.27s
     Running unittests src/lib.rs (target/debug/deps/adder-526769bbba97b5af)

running 1 test
test tests::it_adds_two ... ok

test result: ok. 1 passed; 0 failed; 0 ignored; 0 measured; 0 filtered out; finished in 0.00s

   Doc-tests adder

running 0 tests

test result: ok. 0 passed; 0 failed; 0 ignored; 0 measured; 0 filtered out; finished in 0.00s
```

手动引入 BUG，将 `src/lib.rs` 中的 `add_two` 函数修改为：

```rust
pub fn add_two(a: i32) -> i32 {
    a + 3
}
```

再次 `cargo test` 运行测试：

```bash
$ cargo test
   Compiling adder v0.1.0 (/home/endruz/code/endruz/hello-rust/11.1/adder)
    Finished test [unoptimized + debuginfo] target(s) in 0.25s
     Running unittests src/lib.rs (target/debug/deps/adder-526769bbba97b5af)

running 1 test
test tests::it_adds_two ... FAILED

failures:

---- tests::it_adds_two stdout ----
thread 'tests::it_adds_two' panicked at 'assertion failed: `(left == right)`
  left: `4`,
 right: `5`', src/lib.rs:7:9
note: run with `RUST_BACKTRACE=1` environment variable to display a backtrace


failures:
    tests::it_adds_two

test result: FAILED. 0 passed; 1 failed; 0 ignored; 0 measured; 0 filtered out; finished in 0.00s

error: test failed, to rerun pass '--lib'
```

需要注意的是，在一些语言和测试框架中，断言两个值相等的函数的参数叫做 `expected` 和 `actual`，而且指定参数的顺序是很关键的。然而在 Rust 中，他们则叫做 `left` 和 `right`，同时指定期望的值和被测试代码产生的值的顺序并不重要。这个测试中的断言也可以写成 `assert_eq!(add_two(2), 4)`，这时失败信息会变成 "assertion failed: `(left == right)`" 其中 `left` 是 5 而 `right` 是 4。

`assert_eq!` 和 `assert_ne!` 宏在底层分别使用了 `==` 和 `!=`。当断言失败时，这些宏会使用调试格式打印出其参数，这意味着被比较的值必需实现了 `PartialEq` 和 `Debug` trait。所有的基本类型和大部分标准库类型都实现了这些 trait。对于自定义的结构体和枚举，需要实现 `PartialEq` 才能断言他们的值是否相等。需要实现 `Debug` 才能在断言失败时打印他们的值。因为这两个 trait 都是派生 trait，通常可以直接在结构体或枚举上添加 `#[derive(PartialEq, Debug)]` 注解。

## 自定义失败信息

你也可以向 `assert!`、`assert_eq!` 和 `assert_ne!` 宏传递一个可选的失败信息参数，可以在测试失败时将自定义失败信息一同打印出来。任何在 `assert!` 的一个必需参数和 `assert_eq!` 和 `assert_ne!` 的两个必需参数之后指定的参数都会传递给 `format!` 宏，所以可以传递一个包含 `{}` 占位符的格式字符串和需要放入占位符的值。自定义信息有助于记录断言的意义；当测试失败时就能更好的理解代码出了什么问题。

`src/lib.rs` 内容如下：

```rust
#[cfg(test)]
mod tests {
    use super::*;

    #[test]
    fn greeting_contains_name() {
        let result = greeting("Carol");
        assert!(
            result.contains("Carol"),
            "Greeting did not contain name, value was `{}`",
            result
        );
    }
}

pub fn greeting(name: &str) -> String {
    format!("Hello {}!", name)
}
```

手动引入 BUG，将 `src/lib.rs` 中的 `greeting` 函数修改为：

```rust
pub fn greeting(name: &str) -> String {
    String::from("Hello!")
}
```

运行测试会产生：

```bash
$ cargo test
   Compiling adder v0.1.0 (/home/endruz/code/endruz/hello-rust/11.1/adder)
    Finished test [unoptimized + debuginfo] target(s) in 0.33s
     Running unittests src/lib.rs (target/debug/deps/adder-526769bbba97b5af)

running 1 test
test tests::greeting_contains_name ... FAILED

failures:

---- tests::greeting_contains_name stdout ----
thread 'tests::greeting_contains_name' panicked at 'Greeting did not contain name, value was `Hello!`', src/lib.rs:8:9
note: run with `RUST_BACKTRACE=1` environment variable to display a backtrace


failures:
    tests::greeting_contains_name

test result: FAILED. 0 passed; 1 failed; 0 ignored; 0 measured; 0 filtered out; finished in 0.00s

error: test failed, to rerun pass '--lib'
```

## 使用 should_panic 检查 panic

除了检查代码是否返回期望的正确的值之外，检查代码是否按照期望处理错误也是很重要的。

可以通过对函数增加另一个属性 `should_panic` 来实现这些。这个属性在函数中的代码 panic 时会通过，而在其中的代码没有 panic 时失败。

`src/lib.rs` 内容如下：

```rust
#[cfg(test)]
mod tests {
    use super::*;

    #[test]
    #[should_panic]
    fn greater_than_100() {
        Guess::new(200);
    }
}

pub struct Guess {
    value: i32,
}

impl Guess {
    pub fn new(value: i32) -> Guess {
        if value < 1 || value > 100 {
            panic!("Guess value must be between 1 and 100, got {}.", value);
        }

        Guess { value }
    }
}
```

`#[should_panic]` 属性位于 `#[test]` 之后，这时运行测试会通过。

手动引入 BUG，移除 `new` 函数在值大于 100 时会 panic 的条件修改：

```rust
impl Guess {
    pub fn new(value: i32) -> Guess {
        if value < 1 {
            panic!("Guess value must be between 1 and 100, got {}.", value);
        }

        Guess { value }
    }
}
```

再次运行测试：

```bash
$ cargo test
   Compiling adder v0.1.0 (/home/endruz/code/endruz/hello-rust/11.1/adder)
    Finished test [unoptimized + debuginfo] target(s) in 0.30s
     Running unittests src/lib.rs (target/debug/deps/adder-526769bbba97b5af)

running 1 test
test tests::greater_than_100 - should panic ... FAILED

failures:

---- tests::greater_than_100 stdout ----
note: test did not panic as expected

failures:
    tests::greater_than_100

test result: FAILED. 0 passed; 1 failed; 0 ignored; 0 measured; 0 filtered out; finished in 0.00s

error: test failed, to rerun pass '--lib'
```

并没有得到非常有用的信息，可以给 `should_panic` 属性增加一个可选的 `expected` 参数。测试工具会确保错误信息中包含其提供的文本。

```rust
#[cfg(test)]
mod tests {
    use super::*;

    #[test]
    #[should_panic(expected = "Guess value must be less than or equal to 100")]
    fn greater_than_100() {
        Guess::new(200);
    }
}

pub struct Guess {
    value: i32,
}

impl Guess {
    pub fn new(value: i32) -> Guess {
        if value < 1 {
            panic!(
                "Guess value must be greater than or equal to 1, got {}.",
                value
            );
        } else if value > 100 {
            panic!(
                "Guess value must be less than or equal to 100, got {}.",
                value
            );
        }

        Guess { value }
    }
}
```

这个测试会通过，因为 `should_panic` 属性中 `expected` 参数提供的值是 `Guess::new` 函数 `panic` 信息的子串。我们可以指定期望的整个 `panic` 信息，在这个例子中是 `Guess value must be less than or equal to 100, got 200. `。`expected` 信息的选择取决于 `panic` 信息有多独特或动态。

再次引入一个 BUG，将 `if value < 1` 和 `else if value > 100` 的代码块对换：

```rust
impl Guess {
    pub fn new(value: i32) -> Guess {
        if value < 1 {
            panic!(
                "Guess value must be less than or equal to 100, got {}.",
                value
            );
        } else if value > 100 {
            panic!(
                "Guess value must be greater than or equal to 1, got {}.",
                value
            );
        }

        Guess { value }
    }
}
```

再次运行测试会产生：

```bash
$ cargo test
   Compiling adder v0.1.0 (/home/endruz/code/endruz/hello-rust/11.1/adder)
    Finished test [unoptimized + debuginfo] target(s) in 0.26s
     Running unittests src/lib.rs (target/debug/deps/adder-526769bbba97b5af)

running 1 test
test tests::greater_than_100 - should panic ... FAILED

failures:

---- tests::greater_than_100 stdout ----
thread 'tests::greater_than_100' panicked at 'Guess value must be greater than or equal to 1, got 200.', src/lib.rs:131:13
note: run with `RUST_BACKTRACE=1` environment variable to display a backtrace
note: panic did not contain expected string
      panic message: `"Guess value must be greater than or equal to 1, got 200."`,
 expected substring: `"Guess value must be less than or equal to 100"`

failures:
    tests::greater_than_100

test result: FAILED. 0 passed; 1 failed; 0 ignored; 0 measured; 0 filtered out; finished in 0.00s

error: test failed, to rerun pass '--lib'
```

## 将 Result<T, E> 用于测试

目前为止，我们编写的测试在失败时就会 panic。也可以使用 `Result<T, E>` 编写测试！这里是第一个例子采用了 `Result`：

```rust
#[cfg(test)]
mod tests {
    #[test]
    fn it_works() -> Result<(), String> {
        if 2 + 2 == 4 {
            Ok(())
        } else {
            Err(String::from("two plus two does not equal four"))
        }
    }
}
```

现在 `it_works` 函数的返回值类型为 `Result<(), String>`。在函数体中，不同于调用 `assert_eq!` 宏，而是在测试通过时返回 `Ok(())`，在测试失败时返回带有 `String` 的 `Err`。

这样编写测试来返回 `Result<T, E>` 就可以在函数体中使用问号运算符，如此可以方便的编写任何运算符会返回 `Err` 成员的测试。

不能对这些使用 `Result<T, E>` 的测试使用 `#[should_panic]` 注解。为了断言一个操作返回 `Err` 成员，不要使用对 `Result<T, E>` 值使用问号表达式 `?`。而是使用 `assert!(value.is_err())`。
