# 用 Result 处理可恢复的错误

- [用 Result 处理可恢复的错误](#用-result-处理可恢复的错误)
  - [使用 Result](#使用-result)
  - [匹配不同的错误](#匹配不同的错误)
  - [失败时 panic 的简写：unwrap 和 expect](#失败时-panic-的简写unwrap-和-expect)
  - [传播错误](#传播错误)
  - [传播错误的简写：? 运算符](#传播错误的简写-运算符)
  - [哪里可以使用 ? 运算符](#哪里可以使用--运算符)

## 使用 Result

`Result` 枚举，它定义有如下两个成员，`Ok` 和 `Err`：

```rust
enum Result<T, E> {
    Ok(T),
    Err(E),
}
```

`T` 和 `E` 是泛型类型参数，`T` 代表成功时返回的 `Ok` 成员中的数据的类型，而 `E` 代表失败时返回的 `Err` 成员中的错误的类型。

以下为打开文件操作：

```rust
use std::fs::File;

fn main() {
    let f = File::open("hello.txt");
}
```

如何知道 `File::open` 返回类型：

- 查看 [标准库 API 文档](https://doc.rust-lang.org/std/fs/struct.File.html#implementations)
- 直接问编译器！

随意给 `f` 一个类型注解，接着尝试编译代码，编译器会报错类型不匹配，然后错误信息会给出 `f` 的类型是什么。

将 `let f` 语句改为如下：

```rust
let f: u32 = File::open("hello.txt");
```

尝试编译会给出如下输出：

```
$ cargo run
   Compiling error-handling v0.1.0 (/home/endruz/code/endruz/hello-rust/9.2/error-handling)
error[E0308]: mismatched types
 --> src/main.rs:4:18
  |
4 |     let f: u32 = File::open("hello.txt");
  |            ---   ^^^^^^^^^^^^^^^^^^^^^^^ expected `u32`, found enum `Result`
  |            |
  |            expected due to this
  |
  = note: expected type `u32`
             found enum `Result<File, std::io::Error>`

For more information about this error, try `rustc --explain E0308`.
error: could not compile `error-handling` due to previous error
```

告诉我们了 `File::open` 函数的返回值类型是 `Result<File, std::io::Error>`。

以下代码使用 `match` 来处理 `Result`：

```rust
use std::fs::File;

fn main() {
    let f = File::open("hello.txt");

    let f = match f {
        Ok(file) => file,
        Err(error) => panic!("Problem opening the file: {:?}", error),
    };
}
```

与 `Option` 枚举一样，`Result` 枚举和其成员也被导入到了 prelude 中，所以就不需要在 `match` 分支中的 `Ok` 和 `Err` 之前指定 `Result::`。

## 匹配不同的错误

```rust
use std::fs::File;
use std::io::ErrorKind;

fn main() {
    let f = File::open("hello.txt");

    let f = match f {
        Ok(file) => file,
        Err(error) => match error.kind() {
            ErrorKind::NotFound => match File::create("hello.txt") {
                Ok(fc) => fc,
                Err(e) => panic!("Problem creating the file: {:?}", e),
            },
            other_error => {
                panic!("Problem opening the file: {:?}", other_error)
            }
        },
    };
}
```

## 失败时 panic 的简写：unwrap 和 expect

`match` 有点冗长并且不总是能很好的表明其意图。`Result<T, E>` 类型定义了很多辅助方法来处理各种情况，其中之一叫做 `unwrap`。

如果 `Result` 值是成员 `Ok`，`unwrap` 会返回 `Ok` 中的值。如果 `Result` 是成员 `Err`，`unwrap` 会为我们调用 `panic!`。

```rust
use std::fs::File;

fn main() {
    let f = File::open("hello.txt").unwrap();
}
```

当不存在 hello.txt 文件时，运行后课看到一个 `unwrap` 调用 `panic!` 时提供的错误信息：

```rust
thread 'main' panicked at 'called `Result::unwrap()` on an `Err` value: Os { code: 2, kind: NotFound, message: "No such file or directory" }', src/main.rs:4:37
```

还有另一个类似于 `unwrap` 的方法它还允许自定义 `panic!` 的错误信息：`expect`。使用 `expect` 而不是 `unwrap` 并提供一个好的错误信息可以表明你的意图并更易于追踪 panic 的根源。`expect` 的语法看起来像这样：

```rust
use std::fs::File;

fn main() {
    let f = File::open("hello.txt").expect("Failed to open hello.txt");
}
```

`expect` 返回的错误信息如下：

```
thread 'main' panicked at 'Failed to open hello.txt: Os { code: 2, kind: NotFound, message: "No such file or directory" }', src/main.rs:4:37
```

## 传播错误

当编写一个会调用一些可能会失败的操作的函数时，除了在这个函数中处理错误外，还可以选择让调用者知道这个错误并决定该如何处理，这被称为 **传播（propagating）错误**。

```rust
use std::fs::File;
use std::io::{self, Read};

fn read_username_from_file() -> Result<String, io::Error> {
    let f = File::open("hello.txt");

    let mut f = match f {
        Ok(file) => file,
        // 提前结束函数，返回 File::open 的错误值
        Err(e) => return Err(e),
    };

    let mut s = String::new();

    // 将文件的内容读取到 s 中
    match f.read_to_string(&mut s) {
        // 内容读取成功，将 s 封装进 Ok 中返回。
        Ok(_) => Ok(s),
        // 内容读取失败，返回 read_to_string 的错误值
        Err(e) => Err(e),
    }
}
```

调用这个函数的代码最终会得到一个包含 `String` 的 `Ok` 值，或者一个包含 `io::Error` 的 `Err` 值。我们无从得知调用者会如何处理这些值，所以将所有的成功或失败信息向上传播，让他们选择合适的处理方法。

## 传播错误的简写：? 运算符

下面的例子使用 `?` 运算符实现了和上一个例子相同的功能：

```rust
use std::fs::File;
use std::io;
use std::io::Read;

fn read_username_from_file() -> Result<String, io::Error> {
    let mut f = File::open("hello.txt")?;
    let mut s = String::new();
    f.read_to_string(&mut s)?;
    Ok(s)
}
```

`Result` 值之后的 `?` 运算符工作方式：

- 如果 `Result` 的值是 `Ok`，这个表达式将会返回 `Ok` 中的值而程序将继续执行。
- 如果值是 `Err`，`?` 运算符调用 `from` 函数将收到的错误类型转换为当前函数所指定的返回的错误类型。最后将转换后的 `Err` 作为整个函数的返回值，这样错误值就被传播给了调用者。

> `from` 函数定义于标准库的 `From` trait 中，其用来将错误从一种类型转换为另一种类型。只要每一个错误类型都实现了 `from` 函数来定义如何将自身转换为返回的错误类型，`?` 运算符会自动处理这些转换。

可以在 `?` 之后直接使用链式方法调用来进一步缩短代码：

```rust
use std::fs::File;
use std::io;
use std::io::Read;

fn read_username_from_file() -> Result<String, io::Error> {
    let mut s = String::new();

    File::open("hello.txt")?.read_to_string(&mut s)?;

    Ok(s)
}
```

Rust 提供了名为 `fs::read_to_string` 的函数，它会打开文件、新建一个 `String`、读取文件的内容，并将内容放入 `String`，接着返回它。所以还有一个更短的写法：

```rust
use std::fs;
use std::io;

fn read_username_from_file() -> Result<String, io::Error> {
    fs::read_to_string("hello.txt")
}
```

## 哪里可以使用 ? 运算符

`?` 运算符只能被用于返回值与 `?` 作用的值相兼容的函数。

```rust
use std::fs::File;

fn main() {
    let f = File::open("hello.txt")?;
}
```

`?` 运算符作用于 `File::open` 返回的 `Result` 值，不过 `main` 函数的返回类型是 `()` 而不是 `Result`。当编译这些代码，会得到如下错误信息：

```
$ cargo run
   Compiling error-handling v0.1.0 (/home/endruz/code/endruz/hello-rust/9.2/error-handling)
error[E0277]: the `?` operator can only be used in a function that returns `Result` or `Option` (or another type that implements `FromResidual`)
 --> src/main.rs:4:36
  |
3 | / fn main() {
4 | |     let f = File::open("hello.txt")?;
  | |                                    ^ cannot use the `?` operator in a function that returns `()`
5 | | }
  | |_- this function should return `Result` or `Option` to accept `?`
  |
  = help: the trait `FromResidual<Result<Infallible, std::io::Error>>` is not implemented for `()`

For more information about this error, try `rustc --explain E0277`.
error: could not compile `error-handling` due to previous error
```

错误信息也提到 `?` 也可用于 `Option<T>` 值。如同对 `Result` 使用 `?` 一样，只能在返回 `Option` 的函数中对 `Option` 使用 `?`。在 `Option<T>` 上调用 `?` 运算符的行为与 `Result<T, E>` 类似：如果值是 `None`，此时 `None` 会从函数中提前返回。如果值是 `Some`，`Some` 中的值作为表达式的返回值同时函数继续。

```rust
fn last_char_of_first_line(text: &str) -> Option<char> {
    // 字符串 slice 作为参数并调用其 lines 方法，返回一个字符串中每一行的迭代器。
    // 调用了迭代器 next 来获取迭代器中第一个值，以获取第一行
    // 如果 text 是空字符串，next 调用会返回 None，此时我们可以使用 ? 来停止并从 last_char_of_first_line 返回 None。
    // 如果 text 不是空字符串，next 会返回一个包含 text 中第一行的字符串 slice 的 Some 值。
    text.lines().next()?.chars().last()
}
```

> 注意：可以在返回 `Result` 的函数中对 `Result` 使用 `?` 运算符，可以在返回 `Option` 的函数中对 `Option` 使用 `?` 运算符，但是不可以混合搭配。`?` 运算符不会自动将 `Result` 转化为 `Option`，反之亦然。

目前为止，我们所使用的所有 `main` 函数都返回 `()`。`main` 函数是特殊的因为它是可执行程序的入口点和退出点，为了使程序能正常工作，其可以返回的类型是有限制的。

幸运的是 `main` 函数也可以返回 `Result<(), E>`：

```rust
use std::error::Error;
use std::fs::File;

fn main() -> Result<(), Box<dyn Error>> {
    let f = File::open("hello.txt")?;

    Ok(())
}
```

`Box<dyn Error>` 类型是一个 **trait 对象（trait object）**。目前可以将 `Box<dyn Error>` 理解为 “任何类型的错误”。在返回 `Box<dyn Error>` 错误类型 `main` 函数中对 `Result` 使用 `?` 是允许的，因为它允许任何 `Err` 值提前返回。

当 `main` 函数返回 `Result<(), E>`，如果 `main` 返回 `Ok(())` 可执行程序会以 0 值退出，而如果 `main` 返回 `Err` 值则会以非零值退出；成功退出的程序会返回整数 0，运行错误的程序会返回非 0 的整数。Rust 也会从二进制程序中返回与这个惯例相兼容的整数。
